Workbook

Sheet Dashboard
A1: ZeroTrust.sh · Executive Dashboard
A2: Intern: Ton Minh Hoang · VNG ZingPlay Studio · Date range: 2026-06-11 to 2026-08-06
A4: PROJECT KPIs
A5: Total Tasks | B5: Completed | C5: In Progress | D5: Blocked | E5: Days to Deadline | F5: % Complete
A6: =COUNTIF('G1 - Foundation'!C:C,"TASK")+COUNTIF('G2 - Path A'!C:C,"TASK")+COUNTIF('G3 - Path B'!C:C,"TASK")+COUNTIF('G4 - Integration'!C:C,"TASK")+COUNTIF('Research'!C:C,"TASK") | B6: =COUNTIFS('G1 - Foundation'!C:C,"TASK",'G1 - Foundation'!K:K,"Complete")+COUNTIFS('G2 - Path A'!C:C,"TASK",'G2 - Path A'!K:K,"Complete")+COUNTIFS('G3 - Path B'!C:C,"TASK",'G3 - Path B'!K:K,"Complete")+COUNTIFS('G4 - Integration'!C:C,"TASK",'G4 - Integration'!K:K,"Complete")+COUNTIFS('Research'!C:C,"TASK",'Research'!K:K,"Complete") | C6: =COUNTIFS('G1 - Foundation'!C:C,"TASK",'G1 - Foundation'!K:K,"In Progress")+COUNTIFS('G2 - Path A'!C:C,"TASK",'G2 - Path A'!K:K,"In Progress")+COUNTIFS('G3 - Path B'!C:C,"TASK",'G3 - Path B'!K:K,"In Progress")+COUNTIFS('G4 - Integration'!C:C,"TASK",'G4 - Integration'!K:K,"In Progress")+COUNTIFS('Research'!C:C,"TASK",'Research'!K:K,"In Progress") | D6: =COUNTIFS('G1 - Foundation'!C:C,"TASK",'G1 - Foundation'!K:K,"Blocked")+COUNTIFS('G2 - Path A'!C:C,"TASK",'G2 - Path A'!K:K,"Blocked")+COUNTIFS('G3 - Path B'!C:C,"TASK",'G3 - Path B'!K:K,"Blocked")+COUNTIFS('G4 - Integration'!C:C,"TASK",'G4 - Integration'!K:K,"Blocked")+COUNTIFS('Research'!C:C,"TASK",'Research'!K:K,"Blocked") | E6: =DATE(2026,8,6)-TODAY() | F6: =B6/A6
A8: PROGRESS BY GOAL
A9: Goal | B9: Not Started | C9: In Progress | D9: Complete | E9: Blocked | F9: Total Tasks | G9: % Done
A10: G1 — Foundation & Detection Scaffold | B10: =COUNTIFS('G1 - Foundation'!C:C,"TASK",'G1 - Foundation'!K:K,"Not Started") | C10: =COUNTIFS('G1 - Foundation'!C:C,"TASK",'G1 - Foundation'!K:K,"In Progress") | D10: =COUNTIFS('G1 - Foundation'!C:C,"TASK",'G1 - Foundation'!K:K,"Complete") | E10: =COUNTIFS('G1 - Foundation'!C:C,"TASK",'G1 - Foundation'!K:K,"Blocked") | F10: =COUNTIF('G1 - Foundation'!C:C,"TASK") | G10: =D10/F10
A11: G2 — Path A: CPG + Taint + LLM Verifier | B11: =COUNTIFS('G2 - Path A'!C:C,"TASK",'G2 - Path A'!K:K,"Not Started") | C11: =COUNTIFS('G2 - Path A'!C:C,"TASK",'G2 - Path A'!K:K,"In Progress") | D11: =COUNTIFS('G2 - Path A'!C:C,"TASK",'G2 - Path A'!K:K,"Complete") | E11: =COUNTIFS('G2 - Path A'!C:C,"TASK",'G2 - Path A'!K:K,"Blocked") | F11: =COUNTIF('G2 - Path A'!C:C,"TASK") | G11: =D11/F11
A12: G3 — Path B: Semantic Cost Funnel | B12: =COUNTIFS('G3 - Path B'!C:C,"TASK",'G3 - Path B'!K:K,"Not Started") | C12: =COUNTIFS('G3 - Path B'!C:C,"TASK",'G3 - Path B'!K:K,"In Progress") | D12: =COUNTIFS('G3 - Path B'!C:C,"TASK",'G3 - Path B'!K:K,"Complete") | E12: =COUNTIFS('G3 - Path B'!C:C,"TASK",'G3 - Path B'!K:K,"Blocked") | F12: =COUNTIF('G3 - Path B'!C:C,"TASK") | G12: =D12/F12
A13: G4 — Integration, Report & Demo | B13: =COUNTIFS('G4 - Integration'!C:C,"TASK",'G4 - Integration'!K:K,"Not Started") | C13: =COUNTIFS('G4 - Integration'!C:C,"TASK",'G4 - Integration'!K:K,"In Progress") | D13: =COUNTIFS('G4 - Integration'!C:C,"TASK",'G4 - Integration'!K:K,"Complete") | E13: =COUNTIFS('G4 - Integration'!C:C,"TASK",'G4 - Integration'!K:K,"Blocked") | F13: =COUNTIF('G4 - Integration'!C:C,"TASK") | G13: =D13/F13
A14: Scientific Research | B14: =COUNTIFS('Research'!C:C,"TASK",'Research'!K:K,"Not Started") | C14: =COUNTIFS('Research'!C:C,"TASK",'Research'!K:K,"In Progress") | D14: =COUNTIFS('Research'!C:C,"TASK",'Research'!K:K,"Complete") | E14: =COUNTIFS('Research'!C:C,"TASK",'Research'!K:K,"Blocked") | F14: =COUNTIF('Research'!C:C,"TASK") | G14: =D14/F14
A15: TOTAL | B15: =SUM(B10:B14) | C15: =SUM(C10:C14) | D15: =SUM(D10:D14) | E15: =SUM(E10:E14) | F15: =SUM(F10:F14) | G15: =D15/F15
A17: UPCOMING MILESTONES (next 7 days)
A18: Goal | B18: Milestone ID | C18: Milestone Name | D18: Due Date | E18: Status
A19: G1 | B19: 1.M1 | C19: Semgrep + ast-grep Rule Suite | D19: 2026-06-16 | E19: In Progress
A20: G1 | B20: 1.M2 | C20: Go CLI Core | D20: 2026-06-20 | E20: Not Started
A21: G1 | B21: 1.M3 | C21: Ingestion Layer — MIV + Differential Indexer | D21: 2026-06-25 | E21: Not Started
A22: Research | B22: R.M1 | C22: Literature Foundation | D22: 2026-06-20 | E22: In Progress
A23: G1 | B23: 1.M4 | C23: Canonical Finding Schema + CLI Output | D23: 2026-06-27 | E23: Not Started
A25: INTERNSHIP TIMELINE
A26: Goal | B26: Jun W3 Jun 16–22 | C26: Jun W4 Jun 23–29 | D26: Jul W1 Jun 30–Jul 6 | E26: Jul W2 Jul 7–13 | F26: Jul W3 Jul 14–20 | G26: Jul W4 Jul 21–27 | H26: Aug W1 Jul 28–Aug 6
A27: G1 — Foundation | B27: ▓ | C27: ▓
A28: G2 — Path A | D28: ▓ | E28: ▓ | F28: ▓
A29: G3 — Path B | G29: ▓ | H29: ▓
A30: G4 — Integration | H30: ▓
A31: Research (all goals) | B31: ▓ | C31: ▓ | D31: ▓ | E31: ▓ | F31: ▓ | G31: ▓ | H31: ▓

Sheet G1 - Foundation
A1: ZeroTrust.sh · G1 — Foundation & Detection Scaffold
A2: Intern: Ton Minh Hoang · VNG ZingPlay Studio · Goal: Rule suite + Go CLI + Ingestion layer + Finding schema · Deadline: 2026-06-27
A4: ID | B4: Name | C4: Type | D4: Start Date | E4: End Date | F4: PERT O (h) | G4: PERT ML (h) | H4: PERT P (h) | I4: PERT E (h) | J4: Actual Hrs | K4: Status | L4: Owner | M4: Notes
A5: 1.M1 | B5: Semgrep + ast-grep Rule Suite | C5: MILESTONE | D5: 2026-06-11 | E5: 2026-06-16 | F5: 14 | G5: 20 | H5: 30 | I5: 20.7 | K5: In Progress | M5: Python rules in progress (per CLAUDE.md); Java rules not yet started
A6: 1.M1.T1 | B6: Build synthetic vulnerable test codebase (Python + Java) | C6: TASK | I6: 3 | K6: In Progress | L6: Hoang | M6: Must exist before rules can be validated; trigger every rule class
A7: 1.M1.T2 | B7: Semgrep rules — LLM prompt injection patterns | C7: TASK | I7: 2 | K7: In Progress | L7: Hoang | M7: Python rules in progress; cover direct + indirect injection
A8: 1.M1.T3 | B8: Semgrep rules — security-control bypass comments | C8: TASK | I8: 1.5 | K8: Not Started | L8: Hoang | M8: e.g. # nosec, // nolint, AI-inserted disable comments
A9: 1.M1.T4 | B9: Semgrep rules — hardcoded AI API keys | C9: TASK | I9: 1.5 | K9: Not Started | L9: Hoang | M9: OpenAI, Anthropic, Cohere, HuggingFace key patterns
A10: 1.M1.T5 | B10: Semgrep rules — MCP server config injection (.mcp.json) | C10: TASK | I10: 2 | K10: Not Started | L10: Hoang | M10: Novel surface; no community rules exist; highest-priority unique claim
A11: 1.M1.T6 | B11: Semgrep rules — agent instruction file injection (.cursor/rules, AGENTS.md, CLAUDE.md, GEMINI.md, copilot-instructions.md) | C11: TASK | I11: 2.5 | K11: Not Started | L11: Hoang | M11: First tool to cover this vector; key demo talking point
A12: 1.M1.T7 | B12: ast-grep structural matching rules (languages with weak Semgrep community packs) | C12: TASK | I12: 3 | K12: Not Started | L12: Hoang | M12: YAML rule format; target Rust, Kotlin, C# gaps in Semgrep OSS packs
A13: 1.M1.T8 | B13: Rule validation + false-positive audit against test codebase | C13: TASK | I13: 3 | K13: Not Started | L13: Hoang | M13: Each rule must fire on >= 1 test case; zero FPs on a clean-code control
A14: 1.M1.T9 | B14: CI-runnable test harness | C14: TASK | I14: 2.2 | K14: Not Started | L14: Hoang | M14: Makefile or shell script; pass/fail output per rule class; runs in < 60s
A16: 1.M2 | B16: Go CLI Core | C16: MILESTONE | D16: 2026-06-16 | E16: 2026-06-20 | F16: 12 | G16: 18 | H16: 26 | I16: 18.3 | K16: Not Started | M16: Claude Code compresses ML est. ~35%; single binary from day one
A17: 1.M2.T1 | B17: Go module init + project directory structure | C17: TASK | I17: 1 | K17: Not Started | L17: Hoang | M17: Go 1.22+; cmd/, internal/, pkg/ layout; add .gitignore
A18: 1.M2.T2 | B18: CLI argument parsing + TOML config schema | C18: TASK | I18: 3 | K18: Not Started | L18: Hoang | M18: cobra + viper (or stdlib flag); config fields: model-path, output-dir, scan-target, log-level
A19: 1.M2.T3 | B19: Directory walk + file-type detection (language routing table) | C19: TASK | I19: 3 | K19: Not Started | L19: Hoang | M19: filepath.WalkDir; extension -> language enum map; respect .gitignore
A20: 1.M2.T4 | B20: ZIP archive extract + ingestion path | C20: TASK | I20: 2 | K20: Not Started | L20: Hoang | M20: archive/zip; extract to OS temp dir; cleanup on exit (defer)
A21: 1.M2.T5 | B21: Pluggable Finding channel interface definition | C21: TASK | I21: 3.5 | K21: Not Started | L21: Hoang | M21: chan Finding or writer interface; all pipeline components write here; schema frozen after M1.4
A22: 1.M2.T6 | B22: Cross-compile build pipeline (darwin/linux/windows, amd64/arm64) | C22: TASK | I22: 2 | K22: Not Started | L22: Hoang | M22: Makefile targets; GoReleaser optional; verify binary size < 20 MB
A23: 1.M2.T7 | B23: Smoke test on real directory + binary install verification | C23: TASK | I23: 3.8 | K23: Not Started | L23: Hoang | M23: Binary accepts path arg, scans synthetic codebase, exits 0; test on macOS + Linux
A25: 1.M3 | B25: Ingestion Layer — Model Integrity Verifier + Differential Indexer | C25: MILESTONE | D25: 2026-06-20 | E25: 2026-06-25 | F25: 12 | G25: 18 | H25: 28 | I25: 18.7 | K25: Not Started | M25: MIV is a unique security property vs all competitors; demo talking point
A26: 1.M3.T1 | B26: Model Integrity Verifier: SHA256 hash function for GGUF file | C26: TASK | I26: 1 | K26: Not Started | L26: Hoang | M26: crypto/sha256; stream file in chunks to avoid OOM on large (4-8 GB) models
A27: 1.M3.T2 | B27: Model Integrity Verifier: pinned manifest format + loader | C27: TASK | I27: 2 | K27: Not Started | L27: Hoang | M27: JSON manifest: model name, version, expected SHA256; bundled in binary via go:embed
A28: 1.M3.T3 | B28: Model Integrity Verifier: startup check — block scan + user-facing error on mismatch | C28: TASK | I28: 2 | K28: Not Started | L28: Hoang | M28: Exit code 1 + clear error message; never silently continue on mismatch
A29: 1.M3.T4 | B29: Differential Indexer: per-file hash computation | C29: TASK | I29: 2 | K29: Not Started | L29: Hoang | M29: xxHash (faster) or SHA256 per file; parallel via goroutines over file list
A30: 1.M3.T5 | B30: Differential Indexer: hash cache store | C30: TASK | I30: 2.5 | K30: Not Started | L30: Hoang | M30: BoltDB at ~/.zerotrust/cache/<project-hash>.db; JSON flat-file as fallback
A31: 1.M3.T6 | B31: Differential Indexer: dirty-file computation (current vs cached hash diff) | C31: TASK | I31: 2 | K31: Not Started | L31: Hoang | M31: Returns []FileEntry of changed + new files only; passes to pipeline entry point
A32: 1.M3.T7 | B32: Differential Indexer: cache update on successful scan completion | C32: TASK | I32: 1.5 | K32: Not Started | L32: Hoang | M32: Only write on clean exit (code 0); never persist partial scan state
A33: 1.M3.T8 | B33: Integration test: tampered GGUF file -> scan blocked | C33: TASK | I33: 2.5 | K33: Not Started | L33: Hoang | M33: Flip one byte in model file; assert exit code 1 + correct error message
A34: 1.M3.T9 | B34: Integration test: repeat scan -> only changed files re-scanned | C34: TASK | I34: 3.2 | K34: Not Started | L34: Hoang | M34: Full scan, modify 1 file, rescan; assert only modified file enters pipeline
A36: 1.M4 | B36: Canonical Finding Schema + CLI Output | C36: MILESTONE | D36: 2026-06-25 | E36: 2026-06-27 | F36: 6 | G36: 10 | H36: 16 | I36: 10.3 | K36: Not Started | M36: Schema locked after this milestone — no breaking changes in G2/G3/G4
A37: 1.M4.T1 | B37: Finding struct definition in Go | C37: TASK | I37: 2 | K37: Not Started | L37: Hoang | M37: Fields: CWE, Severity, File, LineStart, LineEnd, Source, Confidence, Evidence, TaintPath (omitempty)
A38: 1.M4.T2 | B38: Severity tier constants (BLOCK / HIGH / MEDIUM / LOW / SUPPRESSED) | C38: TASK | I38: 0.5 | K38: Not Started | L38: Hoang | M38: Typed string constants — not bare strings; use in all components
A39: 1.M4.T3 | B39: JSON serialization for Finding struct | C39: TASK | I39: 2 | K39: Not Started | L39: Hoang | M39: encoding/json; omitempty on optional fields; test marshal/unmarshal roundtrip
A40: 1.M4.T4 | B40: Human-readable stdout formatter (colorized, grouped by severity) | C40: TASK | I40: 3 | K40: Not Started | L40: Hoang | M40: BLOCK=red, HIGH=orange, MEDIUM=yellow, LOW=blue; respect NO_COLOR env var
A41: 1.M4.T5 | B41: Unit tests: struct construction, JSON serialization, stdout output | C41: TASK | I41: 2.8 | K41: Not Started | L41: Hoang | M41: Table-driven tests; golden file for stdout formatter output
A43: 1.BUF | B43: G1 Buffer | C43: BUFFER | D43: 2026-06-11 | E43: 2026-06-27 | I43: 10 | M43: Absorbs: Joern env surprises (R-01), tool version mismatches, sick days; cut stretch items before touching buffer

Sheet G2 - Path A
A1: ZeroTrust.sh · G2 — Path A: CPG + Taint + LLM Verifier
A2: Intern: Ton Minh Hoang · VNG ZingPlay Studio · Goal: Joern CPG + taint queries + Python worker IPC + LLM Verifier · Deadline: 2026-07-18
A4: ID | B4: Name | C4: Type | D4: Start Date | E4: End Date | F4: PERT O (h) | G4: PERT ML (h) | H4: PERT P (h) | I4: PERT E (h) | J4: Actual Hrs | K4: Status | L4: Owner | M4: Notes
A5: 2.M1 | B5: Joern CPG Build Pipeline | C5: MILESTONE | D5: 2026-06-30 | E5: 2026-07-07 | F5: 16 | G5: 25 | H5: 40 | I5: 26 | K5: Not Started | M5: Highest-risk milestone in plan; Joern env setup is the most common blocker; plan for 1-2 debug days
A6: 2.M1.T1 | B6: Joern installation + JVM setup + version-pin | C6: TASK | I6: 2 | K6: Not Started | L6: Hoang | M6: Pin exact Joern version in config (e.g. v4.x); Java 11+; confirm `joern --version` exits 0
A7: 2.M1.T2 | B7: Joern server startup verification | C7: TASK | I7: 2.5 | K7: Not Started | L7: Hoang | M7: Start Joern in server mode; send a no-op query; confirm response; measure cold-start time
A8: 2.M1.T3 | B8: Go subprocess wrapper: spawn Joern process via os/exec | C8: TASK | I8: 4 | K8: Not Started | L8: Hoang | M8: exec.Command; capture stdout/stderr; handle premature exit; log all Joern stderr to debug file
A9: 2.M1.T4 | B9: Go subprocess wrapper: health check + retry logic | C9: TASK | I9: 2.5 | K9: Not Started | L9: Hoang | M9: Poll Joern REST endpoint or REPL; max 3 retries; fail scan with clear error if Joern unresponsive
A10: 2.M1.T5 | B10: CPG generation: invoke Joern on source directory, capture output | C10: TASK | I10: 4.5 | K10: Not Started | L10: Hoang | M10: Feed only dirty files from Differential Indexer; enforce <= 5K LOC gate before invoking; measure build time
A11: 2.M1.T6 | B11: CPG serialization format decision + implementation | C11: TASK | I11: 4 | K11: Not Started | L11: Hoang | M11: Decision: in-memory graph vs file-based export; chosen format must be readable by both Path A and Path B without re-parse
A12: 2.M1.T7 | B12: Shared CPG access interface (Path A + Path B) | C12: TASK | I12: 3.5 | K12: Not Started | L12: Hoang | M12: Go interface with at least: QueryNodes(type), QueryEdges(src, dst), GetCallGraph(); G3 components read from this interface
A13: 2.M1.T8 | B13: Codebase size gate (<= 5K LOC) + query timeout handling | C13: TASK | I13: 2 | K13: Not Started | L13: Hoang | M13: Count LOC before CPG build; reject with user-facing error if over limit; kill Joern process on timeout (default 60s)
A14: 2.M1.T9 | B14: Integration test: CPG built successfully on synthetic test codebase | C14: TASK | I14: 1.3 | K14: Not Started | L14: Hoang | M14: Assert CPG non-empty; assert node types present (Method, Call, Identifier); assert build time < 30s
A16: 2.M2 | B16: Taint Analysis Query Layer | C16: MILESTONE | D16: 2026-07-07 | E16: 2026-07-11 | F16: 14 | G16: 22 | H16: 34 | I16: 22.7 | K16: Not Started | M16: Taint paths produced here are the evidence fed into M2.3 LLM Verifier prompt
A17: 2.M2.T1 | B17: Source / sanitizer / sink taxonomy definition per language | C17: TASK | I17: 3 | K17: Not Started | L17: Hoang | M17: Languages: Java, Python, JS/TS, Go; document each category in a YAML taxonomy file
A18: 2.M2.T2 | B18: Joern traversal queries: external-input source nodes | C18: TASK | I18: 3.5 | K18: Not Started | L18: Hoang | M18: Scala DSL; sources: HTTP params, env vars, file reads, stdin, deserialized objects
A19: 2.M2.T3 | B19: Joern traversal queries: sanitizer nodes | C19: TASK | I19: 3.5 | K19: Not Started | L19: Hoang | M19: Sanitizers: input validation, HTML encoding, parameterized queries, allowlist checks
A20: 2.M2.T4 | B20: Joern traversal queries: dangerous sink nodes | C20: TASK | I20: 3.5 | K20: Not Started | L20: Hoang | M20: Sinks: eval, exec/system, SQL string concat, deserialize, file write to user-controlled path, SSRF URL construction
A21: 2.M2.T5 | B21: Taint flow -> Finding struct mapping + CWE assignment | C21: TASK | I21: 3.5 | K21: Not Started | L21: Hoang | M21: Each taint flow serialized: source node, sanitizer gaps, sink node, traversal path; CWE assigned by sink type
A22: 2.M2.T6 | B22: Multi-language taint query test suite | C22: TASK | I22: 3 | K22: Not Started | L22: Hoang | M22: One taint case per language (Java, Python, JS/TS, Go); each must be detected; add to CI harness
A23: 2.M2.T7 | B23: False positive baseline measurement on synthetic clean code | C23: TASK | I23: 2.7 | K23: Not Started | L23: Hoang | M23: Run taint queries on clean-code control set; count FPs; record as baseline before LLM Verifier applied
A25: 2.M3 | B25: Python Worker Bootstrap + LLM Verifier (False Positive Filter) | C25: MILESTONE | D25: 2026-07-11 | E25: 2026-07-16 | F25: 18 | G25: 29 | H25: 42 | I25: 29.3 | K25: Not Started | M25: Two parts: (1) IPC boundary — built once, reused by all G3 ML components; (2) LLM Verifier using XGrammar
A26: 2.M3.T1 | B26: Python venv setup + requirements.txt | C26: TASK | I26: 1.5 | K26: Not Started | L26: Hoang | M26: Packages: xgrammar, ollama (Python client), httpx; pin versions; venv at worker/venv/
A27: 2.M3.T2 | B27: Python worker main.py: message dispatcher | C27: TASK | I27: 3 | K27: Not Started | L27: Hoang | M27: Reads NDJSON from stdin in a loop; dispatches by `type` field (llm_verify, classify, summarize, llm_scan, ping, shutdown)
A28: 2.M3.T3 | B28: Go worker-manager: spawn Python worker via os/exec + pipe setup | C28: TASK | I28: 3.5 | K28: Not Started | L28: Hoang | M28: exec.Command('python3', '-u', 'worker/main.py'); -u disables output buffering; pipe stdin + stdout; route stderr to log
A29: 2.M3.T4 | B29: Go worker-manager: health-check ping + restart-on-crash logic | C29: TASK | I29: 2.5 | K29: Not Started | L29: Hoang | M29: Send ping; await pong; detect closed stdout pipe; attempt 1 restart; fallback to direct Ollama HTTP on second failure
A30: 2.M3.T5 | B30: NDJSON protocol: request/response schema + Go client library | C30: TASK | I30: 3 | K30: Not Started | L30: Hoang | M30: Request: {id, type, payload}; Response: {id, status, result} or {id, status, error}; thread-safe
A31: 2.M3.T6 | B31: Python worker: Ollama HTTP client integration | C31: TASK | I31: 2.5 | K31: Not Started | L31: Hoang | M31: Call Ollama REST API (/api/generate); pass model name from config; handle timeout; verify model loaded
A32: 2.M3.T7 | B32: Python worker: XGrammar JSON schema enforcement on LLM output | C32: TASK | I32: 3 | K32: Not Started | L32: Hoang | M32: Verdict JSON schema: {verified: bool, confidence: float, rationale: str}; XGrammar enforces at generation time
A33: 2.M3.T8 | B33: Taint-flow prompt template | C33: TASK | I33: 3.5 | K33: Not Started | L33: Hoang | M33: Template inputs: taint flow path, sink type, reachability condition, sanitizer gaps; test with 5+ real taint flows
A34: 2.M3.T9 | B34: Verdict routing back to Go Finding channel | C34: TASK | I34: 2 | K34: Not Started | L34: Hoang | M34: verified=true -> write Finding to channel; verified=false -> discard; confidence score written to Finding.Confidence
A35: 2.M3.T10 | B35: Latency benchmark: per-finding round-trip time | C35: TASK | I35: 2 | K35: Not Started | L35: Hoang | M35: Target: < 2s per finding (Go send -> Python -> Ollama -> XGrammar -> Go receive); log p50/p95
A36: 2.M3.T11 | B36: Accuracy test: TP/FP rate on synthetic taint findings | C36: TASK | I36: 2.8 | K36: Not Started | L36: Hoang | M36: Run LLM Verifier on taint findings from M2.2; target >= 88% FP reduction; record as A-18 pre-check
A38: 2.M4 | B38: Path A Integration Test Suite | C38: MILESTONE | D38: 2026-07-16 | E38: 2026-07-18 | F38: 6 | G38: 10 | H38: 16 | I38: 10.3 | K38: Not Started | M38: Natural pause point before G3; Joern CPG confirmed as shared infra; mentor review can be scheduled here
A39: 2.M4.T1 | B39: Synthetic test case set: 10+ vulnerable functions (one per CWE class) | C39: TASK | I39: 3 | K39: Not Started | L39: Hoang | M39: CWE classes: CWE-89 SQL injection, CWE-78 OS command injection, CWE-22 path traversal, CWE-502 deserialization, CWE-611 XXE, CWE-918 SSRF, CWE-79 XSS, CWE-327 weak crypto, CWE-798 hardcoded creds, CWE-94 code injection
A40: 2.M4.T2 | B40: End-to-end pipeline run (ingestion -> Joern -> taint -> LLM Verifier -> Finding output) | C40: TASK | I40: 2 | K40: Not Started | L40: Hoang | M40: Single `zerotrust scan ./test-codebase` command; all 10+ CWE cases must produce Findings
A41: 2.M4.T3 | B41: Precision/recall baseline measurement | C41: TASK | I41: 2 | K41: Not Started | L41: Hoang | M41: Record in docs/benchmarks/g2_baseline.md; this is the baseline G3 Path B will improve on
A42: 2.M4.T4 | B42: Integration break fixes | C42: TASK | I42: 2 | K42: Not Started | L42: Hoang | M42: Resolve any failures found in T2/T3; if a fix takes > 4h, escalate as At Risk and consume buffer
A43: 2.M4.T5 | B43: Performance profiling: full scan time on 5K LOC synthetic codebase | C43: TASK | I43: 1.3 | K43: Not Started | L43: Hoang | M43: Measure: CPG build time, taint query time, LLM Verifier time, total wall clock; target total < 5 min on 5K LOC
A45: 2.BUF | B45: G2 Buffer | C45: BUFFER | D45: 2026-06-30 | E45: 2026-07-18 | I45: 13 | M45: Primary risk: R-01 Joern env setup surprises (OOM, Scala DSL learning curve); secondary: mentor review cycle

Sheet G3 - Path B
A1: ZeroTrust.sh · G3 — Path B: Three-Tier Semantic Cost Funnel
A2: Intern: Ton Minh Hoang · VNG ZingPlay Studio · Goal: Heuristic Targeting + UniXcoder + Semantic Summarizer + LLM ReAct · Deadline: 2026-08-01
A4: ID | B4: Name | C4: Type | D4: Start Date | E4: End Date | F4: PERT O (h) | G4: PERT ML (h) | H4: PERT P (h) | I4: PERT E (h) | J4: Actual Hrs | K4: Status | L4: Owner | M4: Notes
A5: 3.M1 | B5: Heuristic Targeting + Call Graph + CVE Enrichment | C5: MILESTONE | D5: 2026-07-21 | E5: 2026-07-25 | F5: 12 | G5: 18 | H5: 28 | I5: 18.7 | K5: Not Started | M5: Reads Joern CPG from G2 (no re-parse); Trivy replaced by OSV-Scanner (CVE-2026-33634 supply chain compromise)
A6: 3.M1.T1 | B6: CPG node-type queries — external-input nodes | C6: TASK | I6: 2.5 | K6: Not Started | L6: Hoang | M6: Query CPG for HTTP params, env vars, file reads, stdin, deserialized objects; language-agnostic via shared CPG schema
A7: 3.M1.T2 | B7: CPG node-type queries — auth-boundary nodes | C7: TASK | I7: 2 | K7: Not Started | L7: Hoang | M7: Identify authentication/authorization check points; missing guard detection starts here
A8: 3.M1.T3 | B8: CPG node-type queries — AI agent config file nodes | C8: TASK | I8: 2 | K8: Not Started | L8: Hoang | M8: MCP configs, .cursor/rules, AGENTS.md, CLAUDE.md, GEMINI.md; unique detection surface
A9: 3.M1.T4 | B9: Call graph extraction from Joern CPG | C9: TASK | I9: 3 | K9: Not Started | L9: Hoang | M9: No separate build step — call graph comes from CPG built in G2; extract caller/callee edges; output: Go CallGraph struct
A10: 3.M1.T5 | B10: OSV-Scanner Go library integration (github.com/google/osv-scanner/v2) | C10: TASK | I10: 3 | K10: Not Started | L10: Hoang | M10: Direct Go import — no subprocess; scan dependency manifests (go.mod, requirements.txt, pom.xml, package.json)
A11: 3.M1.T6 | B11: CVE exact-match auto-flag + routing to findings | C11: TASK | I11: 2 | K11: Not Started | L11: Hoang | M11: If OSV-Scanner returns exact CVE match -> write Finding directly with severity from CVSS; skip further analysis
A12: 3.M1.T7 | B12: BOLAZ zero-trust resource ID dataflow flagging | C12: TASK | I12: 2.5 | K12: Not Started | L12: Hoang | M12: Flag all external IDs as untrustworthy until explicit authorization confirmed at each function boundary; targets IDOR/BOLA
A13: 3.M1.T8 | B13: Surface list output format for downstream classifier | C13: TASK | I13: 1.7 | K13: Not Started | L13: Hoang | M13: Struct: Surface{ID, File, FunctionName, NodeType, CallGraphDepth, CVEMatches}; passed to M3.2 classifier
A15: 3.M2 | B15: UniXcoder Classifier Gate | C15: MILESTONE | D15: 2026-07-25 | E15: 2026-07-28 | F15: 12 | G15: 18 | H15: 28 | I15: 18.7 | K15: Not Started | M15: Primary LLM cost gate; A-18 calibration point — measure real precision/recall on AI-generated code; window spans weekend
A16: 3.M2.T1 | B16: UniXcoder model load in Python worker (extend dispatcher) | C16: TASK | I16: 2.5 | K16: Not Started | L16: Hoang | M16: Add `classify` type handler to Python worker from G2; load UniXcoder-Base-Nine via transformers; pin model version
A17: 3.M2.T2 | B17: Go IPC: classify request/response type handling | C17: TASK | I17: 2 | K17: Not Started | L17: Hoang | M17: Send Surface struct as payload; receive {verdict: vulnerable/safe/uncertain, confidence: float}; reuse NDJSON protocol
A18: 3.M2.T3 | B18: Confidence threshold calibration (3-band classification) | C18: TASK | I18: 3 | K18: Not Started | L18: Hoang | M18: Tune thresholds: high-conf-safe (dismiss), high-conf-vulnerable (flag direct), uncertain (-> LLM); target uncertain band = 15-25%
A19: 3.M2.T4 | B19: High-confidence-safe dismissal routing | C19: TASK | I19: 1.5 | K19: Not Started | L19: Hoang | M19: Surfaces below safe threshold -> dropped silently; log count for cost funnel stats used in demo
A20: 3.M2.T5 | B20: High-confidence-vulnerable direct Finding flag routing | C20: TASK | I20: 1.5 | K20: Not Started | L20: Hoang | M20: Surfaces above vulnerable threshold -> write Finding directly to channel; no LLM call; Source field = 'UniXcoder'
A21: 3.M2.T6 | B21: Unsupported-language bypass (Rust, Kotlin, Swift, C# -> direct LLM) | C21: TASK | I21: 1.5 | K21: Not Started | L21: Hoang | M21: UniXcoder trained only on Python/Java/JS/TS/Go/Ruby/PHP; unsupported languages skip classifier
A22: 3.M2.T7 | B22: A-18 gap measurement: precision/recall on AI-generated code vs BigVul baseline | C22: TASK | I22: 3.2 | K22: Not Started | L22: Hoang | M22: Run classifier on test codebase (AI-generated code); record F1, precision, recall; compare to claimed F1=94.73% on BigVul
A23: 3.M2.T8 | B23: Classifier gate integration test: verify < 25% of surfaces reach LLM tier | C23: TASK | I23: 3.5 | K23: Not Started | L23: Hoang | M23: Run full surface set through gate; assert uncertain band <= 25%; if over, re-tune thresholds; log final funnel stats
A25: 3.M3 | B25: Call Chain Context Assembler + Semantic Function Summarizer | C25: MILESTONE | D25: 2026-07-28 | E25: 2026-07-31 | F25: 12 | G25: 18 | H25: 28 | I25: 18.7 | K25: Not Started | M25: LLM never receives raw code — only semantic summaries; aligns with IRIS ICLR 2025 design
A26: 3.M3.T1 | B26: Call chain traversal to depth 3 from Joern CPG (caller -> surface -> callee) | C26: TASK | I26: 4 | K26: Not Started | L26: Hoang | M26: Use call graph from 3.M1.T4; traverse depth 3 max; return ordered list [caller, surface, callee]; handle recursive/missing nodes
A27: 3.M3.T2 | B27: Multi-function context assembly (structured call chain representation) | C27: TASK | I27: 3 | K27: Not Started | L27: Hoang | M27: Struct: CallChainContext{functions: []FunctionContext, entryPoint, depth}; FunctionContext: name, params, local vars, calls, return type
A28: 3.M3.T3 | B28: Semantic summary schema — taint-flow vulnerability class | C28: TASK | I28: 2 | K28: Not Started | L28: Hoang | M28: Fields: untrustedDataSource, sanitizersPresent[], sanitizerGaps[], sinkReached, sinkType
A29: 3.M3.T4 | B29: Semantic summary schema — auth-guard vulnerability class | C29: TASK | I29: 2 | K29: Not Started | L29: Hoang | M29: Fields: resourceAccessed, authCheckPresent, authCheckLocation, principalVerified; enables IDOR + missing auth guard detection
A30: 3.M3.T5 | B30: Semantic summary schema — logic-flaw vulnerability class | C30: TASK | I30: 2 | K30: Not Started | L30: Hoang | M30: Fields: businessConstraints[], stateTransitions[], enforcedAtBoundary; targets business logic and state machine flaws
A31: 3.M3.T6 | B31: Function-level semantic abstraction generation (Python worker call) | C31: TASK | I31: 2.5 | K31: Not Started | L31: Hoang | M31: For each FunctionContext in call chain: call Python worker with `summarize` type; assemble into SummarizedCallChain struct
A32: 3.M3.T7 | B32: Token footprint measurement before/after summarization | C32: TASK | I32: 1.5 | K32: Not Started | L32: Hoang | M32: Count tokens in raw call chain vs summarized version; target >= 60% token reduction; log in docs/benchmarks/token_footprint.md
A33: 3.M3.T8 | B33: Multi-function vulnerability detection test (IDOR + missing auth guard) | C33: TASK | I33: 1.7 | K33: Not Started | L33: Hoang | M33: Synthetic test: IDOR case spanning caller (no auth check) + surface (uses external ID) + callee (DB lookup); assert detected
A35: 3.M4 | B35: Token Budget Controller + LLM ReAct Scan + Scan Security Context Store | C35: MILESTONE | D35: 2026-07-31 | E35: 2026-08-01 | F35: 14 | G35: 22 | H35: 36 | I35: 23 | K35: Not Started | M35: T7-T9 are SCSS — explicit DROP CANDIDATES; cut these first if window is tight; ReAct scan works without SCSS
A36: 3.M4.T1 | B36: Surface prioritization ranking (CVE score x classifier uncertainty) | C36: TASK | I36: 2.5 | K36: Not Started | L36: Hoang | M36: Rank uncertain surfaces: (CVSS score from OSV x (1 - classifier confidence)); highest ranked consume token budget first
A37: 3.M4.T2 | B37: Hard per-scan token cap enforcement | C37: TASK | I37: 2 | K37: Not Started | L37: Hoang | M37: Configurable cap (default: 50K tokens per scan); token counter incremented on each LLM call; halt when cap reached
A38: 3.M4.T3 | B38: ReAct loop — Thought step | C38: TASK | I38: 2.5 | K38: Not Started | L38: Hoang | M38: LLM receives: semantic summary + vulnerability class schema; produces Thought: hypothesis + what additional context needed
A39: 3.M4.T4 | B39: ReAct loop — context-request step (call chain depth + CVE lookup) | C39: TASK | I39: 3 | K39: Not Started | L39: Hoang | M39: LLM can request: deeper call chain (up to depth 3), CVE DB lookup from OSV-Scanner, or prior inferences from SCSS
A40: 3.M4.T5 | B40: ReAct loop — Observation -> verdict step | C40: TASK | I40: 2.5 | K40: Not Started | L40: Hoang | M40: Max 3 ReAct steps; final step produces verdict; XGrammar enforces JSON schema; write to Finding channel
A41: 3.M4.T6 | B41: XGrammar schema enforcement on ReAct output (extend Python worker) | C41: TASK | I41: 2 | K41: Not Started | L41: Hoang | M41: Add `llm_scan` type to Python worker dispatcher; XGrammar JSON schema for ReAct verdict
A42: 3.M4.T7 | B42: [SCSS DROP FIRST] Scan Security Context Store: in-memory key-value store per scan | C42: TASK | I42: 3 | K42: Not Started | L42: Hoang | M42: DROP if M3.4 starts late; per-scan map: {surfaceID -> SecurityInference}; stores inferred data sources, sanitizer gaps
A43: 3.M4.T8 | B43: [SCSS DROP FIRST] SCSS read/write hooks on LLM calls | C43: TASK | I43: 2 | K43: Not Started | L43: Hoang | M43: DROP if M3.4 starts late; before ReAct Thought: inject prior inferences from SCSS; after verdict: write new inferences
A44: 3.M4.T9 | B44: [SCSS DROP FIRST] Cross-surface vulnerability detection test | C44: TASK | I44: 3.5 | K44: Not Started | L44: Hoang | M44: DROP if M3.4 starts late; test: vulnerability only detectable by combining inferences from two separate surfaces
...

Sheet G4 - Integration
A1: ZeroTrust.sh · G4 — Integration, Report & Demo
A2: Intern: Ton Minh Hoang · VNG ZingPlay Studio · Goal: Dedup + SSVC scoring + HTML report + end-to-end demo · Deadline: 2026-08-06
A4: ID | B4: Name | C4: Type | D4: Start Date | E4: End Date | F4: PERT O (h) | G4: PERT ML (h) | H4: PERT P (h) | I4: PERT E (h) | J4: Actual Hrs | K4: Status | L4: Owner | M4: Notes
A5: 4.M1 | B5: Dedup + SSVC Confidence Scoring | C5: MILESTONE | D5: 2026-08-01 | E5: 2026-08-03 | F5: 6 | G5: 10 | H5: 16 | I5: 10.3 | K5: Not Started | M5: Skeleton should be pre-stubbed during G3 final week; merges Path A + Path B findings into unified 5-tier output
A6: 4.M1.T1 | B6: Dedup — AST edit distance comparison | C6: TASK | I6: 2 | K6: Not Started | L6: Hoang | M6: Compare evidence snippets from Path A and Path B; collapse duplicates above edit-distance threshold
A7: 4.M1.T2 | B7: Dedup — CWE pattern hash | C7: TASK | I7: 1.5 | K7: Not Started | L7: Hoang | M7: Hash: CWE ID + file path + line range; collapse findings with identical hash; fastest dedup pass, runs first
A8: 4.M1.T3 | B8: Dedup — LLM semantic similarity check (Python worker call) | C8: TASK | I8: 2 | K8: Not Started | L8: Hoang | M8: For findings not collapsed by T1/T2: embed + cosine similarity; collapse if similarity > threshold
A9: 4.M1.T4 | B9: SSVC dimension mapping -> 5-tier score assignment | C9: TASK | I9: 2 | K9: Not Started | L9: Hoang | M9: Dimensions: Exploitation (EPSS from OSV), Automatable (taint path), Technical Impact (sink type); map to BLOCK/HIGH/MEDIUM/LOW/SUPPRESSED
A10: 4.M1.T5 | B10: Cross-path confirmation boost (+15% for findings confirmed by both paths) | C10: TASK | I10: 1 | K10: Not Started | L10: Hoang | M10: If same finding appears in Path A and Path B output (after dedup): boost SSVC score by +15%
A11: 4.M1.T6 | B11: Suppression rules + dedup test suite | C11: TASK | I11: 1.8 | K11: Not Started | L11: Hoang | M11: Suppress: findings in test files (_test.go, test_*.py), framework-safe functions; test suite: 5+ dedup cases, 3+ suppression
A13: 4.M2 | B13: HTML Report Generator + Patch Suggestions | C13: MILESTONE | D13: 2026-08-03 | E13: 2026-08-04 | F13: 6 | G13: 10 | H13: 16 | I13: 10.3 | K13: Not Started | M13: Go html/template + embed only — no Python dependency; output is a single portable .html file
A14: 4.M2.T1 | B14: Go html/template structure + embed setup | C14: TASK | I14: 3 | K14: Not Started | L14: Hoang | M14: //go:embed templates/*; base template with header, severity sections, finding cards; CSS inlined; no CDN dependencies
A15: 4.M2.T2 | B15: Finding list serialization to HTML (severity groups, collapsible evidence panels) | C15: TASK | I15: 2 | K15: Not Started | L15: Hoang | M15: Group findings by SSVC tier (BLOCK first); each finding card: file + line, CWE, rationale, evidence snippet, patch suggestion
A16: 4.M2.T3 | B16: Filter/sort controls (vanilla JS — no framework) | C16: TASK | I16: 2.5 | K16: Not Started | L16: Hoang | M16: Filter by: severity tier, CWE, file path; sort by: SSVC score, file name; ~50 lines of vanilla JS; self-contained
A17: 4.M2.T4 | B17: SSVC score visualization (severity tier badges + dimension breakdown) | C17: TASK | I17: 1 | K17: Not Started | L17: Hoang | M17: Colored badge per tier (BLOCK=red, HIGH=orange, MEDIUM=yellow, LOW=blue, SUPPRESSED=grey); tooltip shows SSVC dimensions
A18: 4.M2.T5 | B18: Patch suggestion prompt template + unified diff output (Python worker call) | C18: TASK | I18: 1.8 | K18: Not Started | L18: Hoang | M18: Zero-shot LLM call via `patch_suggest` type; prompt: finding rationale + code context; output: unified diff
A20: 4.M3 | B20: End-to-End Demo Run + Hardening | C20: MILESTONE | D20: 2026-08-04 | E20: 2026-08-06 | F20: 6 | G20: 10 | H20: 16 | I20: 10.3 | K20: Not Started | M20: Final gate before demo; `zerotrust scan ./target` must work end-to-end; timing must be < 10 min on test codebase
A21: 4.M3.T1 | B21: Source or build 2-3 realistic AI-generated vulnerable codebases | C21: TASK | I21: 2.5 | K21: Not Started | L21: Hoang | M21: Languages: Python (FastAPI/Flask), Go (net/http), Java (Spring Boot); use real AI-agent-generated code where possible
A22: 4.M3.T2 | B22: Full pipeline run on each target codebase | C22: TASK | I22: 2 | K22: Not Started | L22: Hoang | M22: Run `zerotrust scan ./target` end-to-end; verify: GGUF verified at startup, dirty files only re-scanned, HTML report generated
A23: 4.M3.T3 | B23: Integration break fixes | C23: TASK | I23: 2 | K23: Not Started | L23: Hoang | M23: Resolve any pipeline failures from T2; if a fix exceeds 2h, escalate as At Risk; do not introduce new features
A24: 4.M3.T4 | B24: Scan timing measurement (wall clock + per-component breakdown) | C24: TASK | I24: 1 | K24: Not Started | L24: Hoang | M24: Instrument: CPG build time, classifier gate time, LLM call time, total wall clock; target total < 10 min
A25: 4.M3.T5 | B25: Demo script + rehearsal run | C25: TASK | I25: 2.8 | K25: Not Started | L25: Hoang | M25: Script covers: detection found, cost funnel % reached LLM, SSVC score explanation, patch diff, model integrity demo
A27: 4.M4 | B27: PoE Layer — Red Team Agent + Docker Sandbox | C27: STRETCH | D27: 2026-08-04 | E27: 2026-08-06 | I27: 15 | K27: Not Started | M27: STRETCH — CUT FIRST. Do not attempt if any G3 M3.4 task is incomplete on Aug 1. Parallel with M4.3 if attempted.
A28: 4.M4.T1 | B28: [STRETCH] LangGraph workflow setup (Recon -> Exploit -> Verify graph nodes) | C28: TASK | I28: 4 | K28: Not Started | L28: Hoang | M28: Python LangGraph v1.0; 3 nodes with typed state: Reconnaissance, Exploitation, Verification; state machine transitions
A29: 4.M4.T2 | B29: [STRETCH] Docker sandbox: container spec + seccomp profile (network isolation) | C29: TASK | I29: 3.5 | K29: Not Started | L29: Hoang | M29: Go Docker SDK; container: no network, no root, seccomp deny-list; volume mount: target codebase read-only
A30: 4.M4.T3 | B30: [STRETCH] Docker sandbox: attempt-trigger logic for BLOCK/HIGH findings | C30: TASK | I30: 3.5 | K30: Not Started | L30: Hoang | M30: LangGraph Exploitation node generates exploit code; passes to sandbox; captures execution result; timeout = 30s
A31: 4.M4.T4 | B31: [STRETCH] Two-layer PoE output (technical trace + executive summary) | C31: TASK | I31: 2.5 | K31: Not Started | L31: Hoang | M31: Technical trace: exploit code, execution log, sandbox exit code; executive summary: vulnerability name, business impact
A32: 4.M4.T5 | B32: [STRETCH] Static-evidence fallback when sandbox execution fails | C32: TASK | I32: 1.5 | K32: Not Started | L32: Hoang | M32: If sandbox exits non-zero or times out: emit 'Static evidence only — sandbox execution failed'; degrade gracefully
A34: 4.BUF | B34: G4 Buffer | C34: BUFFER | D34: 2026-08-01 | E34: 2026-08-06 | I34: 3 | M34: Tight 10% buffer; primary absorption: integration breaks in M4.3; if M4.4 not attempted, its 15h become additional buffer

Sheet Research
A1: ZeroTrust.sh · Scientific Research & Architecture Validation
A2: Intern: Ton Minh Hoang · VNG ZingPlay Studio · Goal: Evidence-backed architecture validation · Runs Jun 9 – Aug 1
A4: ID | B4: Name | C4: Type | D4: Start Date | E4: End Date | F4: PERT O (h) | G4: PERT ML (h) | H4: PERT P (h) | I4: PERT E (h) | J4: Actual Hrs | K4: Status | L4: Owner | M4: Notes
A5: R.M1 | B5: Literature Foundation | C5: MILESTONE | D5: 2026-06-09 | E5: 2026-06-20 | F5: 20 | G5: 41 | H5: 82 | I5: 44.33 | K5: In Progress | M5: Read and annotate all 40 catalogued papers across 7 areas. Build paper-to-architecture-component linkage map.
A6: R.M1.T1 | B6: Read and annotate Area 1 (Deep Learning & ML for Vulnerability Detection, ~4 papers) and Area 2 (GNN for Vulnerability Detection, ~6 papers) | C6: TASK | I6: 8.67 | K6: In Progress | L6: Hoang
A7: R.M1.T2 | B7: Read and annotate Area 3 (LLM for Code Security Analysis, ~6 papers) | C7: TASK | I7: 12.67 | K7: Not Started | L7: Hoang
A8: R.M1.T3 | B8: Read and annotate Area 4 (Hybrid Static Analysis + LLM, ~5 papers) and Area 5 (AI-Generated Code Security & Prompt Injection, ~5 papers) | C8: TASK | I8: 10.83 | K8: Not Started | L8: Hoang
A9: R.M1.T4 | B9: Read and annotate Area 6 (Token Cost Optimization, ~4 papers) and Area 7 (Call Graph, Taint Analysis & Code Representations, ~10 papers) | C9: TASK | I9: 9 | K9: Not Started | L9: Hoang
A10: R.M1.T5 | B10: Build paper-to-architecture-component linkage map: assign each of the 40 papers to >= 1 ZeroTrust.sh component as primary evidence | C10: TASK | I10: 3.17 | K10: Not Started | L10: Hoang
A12: R.M2 | B12: Architecture Validation Matrix | C12: MILESTONE | D12: 2026-06-16 | E12: 2026-06-27 | F12: 4 | G12: 8.5 | H12: 21 | I12: 9.83 | K12: Not Started | M12: Map every architecture component to >= 1 supporting paper. Flag components with no academic backing as validation gaps.
A13: R.M2.T1 | B13: Map Differential Indexer and all Path A sub-components to >= 1 supporting paper each | C13: TASK | I13: 2.33 | K13: Not Started | L13: Hoang
A14: R.M2.T2 | B14: Map Path B three-tier cost funnel to supporting papers with specific claimed performance figures recorded | C14: TASK | I14: 2.33 | K14: Not Started | L14: Hoang
A15: R.M2.T3 | B15: Map Dedup layer and 5-tier Confidence Scoring to supporting papers | C15: TASK | I15: 1.25 | K15: Not Started | L15: Hoang
A16: R.M2.T4 | B16: Map Proof-of-Exploit Layer to supporting papers on automated vulnerability verification | C16: TASK | I16: 1.75 | K16: Not Started | L16: Hoang
A17: R.M2.T5 | B17: Identify every architecture component with zero academic backing and document each as an open validation gap | C17: TASK | I17: 2.17 | K17: Not Started | L17: Hoang
A19: R.M3 | B19: Benchmark & Performance Claims Verification | C19: MILESTONE | D19: 2026-06-23 | E19: 2026-07-04 | F19: 3 | G19: 6.5 | H19: 18 | I19: 7.83 | K19: Not Started | M19: Verify every quantitative claim in the architecture docs against its source paper.
A20: R.M3.T1 | B20: Verify UniXcoder-Base-Nine F1=94.73% on BigVul: locate original paper, confirm exact evaluation setup | C20: TASK | I20: 1.25 | K20: Not Started | L20: Hoang
A21: R.M3.T2 | B21: Verify 88-93% false positive reduction claim for the LLM Verifier | C21: TASK | I21: 1.75 | K21: Not Started | L21: Hoang
A22: R.M3.T3 | B22: Verify ~80-95% cost reduction claim for the Differential Indexer | C22: TASK | I22: 1.25 | K22: Not Started | L22: Hoang
A23: R.M3.T4 | B23: Verify ~15-25% LLM escalation rate and ~95% file elimination rate | C23: TASK | I23: 1.25 | K23: Not Started | L23: Hoang
A24: R.M3.T5 | B24: Compile benchmarks reference table: claim text, source, confidence level, follow-up action | C24: TASK | I24: 2.33 | K24: Not Started | L24: Hoang
A26: R.M4 | B26: Competitive Landscape Research | C26: MILESTONE | D26: 2026-06-30 | E26: 2026-07-11 | F26: 6 | G26: 12 | H26: 26 | I26: 13.33 | K26: Not Started | M26: Research Semgrep, Snyk Code, and CodeRabbit structural gaps vs ZeroTrust.sh. Compile differentiation evidence table.
A27: R.M4.T1 | B27: Research publicly available accuracy and precision data for Semgrep OSS and Semgrep Pro | C27: TASK | I27: 2.33 | K27: Not Started | L27: Hoang
A28: R.M4.T2 | B28: Research Snyk Code architecture with focus on cloud dependency and source-code-upload requirements | C28: TASK | I28: 2.17 | K28: Not Started | L28: Hoang
A29: R.M4.T3 | B29: Research CodeRabbit's PR-gated workflow architecture: document what it structurally cannot do | C29: TASK | I29: 2.17 | K29: Not Started | L29: Hoang
A30: R.M4.T4 | B30: Search academic databases for evidence that local-only execution with AI-specific threat detection is under-served | C30: TASK | I30: 4.5 | K30: Not Started | L30: Hoang
A31: R.M4.T5 | B31: Compile differentiation evidence table: ZeroTrust.sh differentiator, evidence source, competitor, gap type | C31: TASK | I31: 2.17 | K31: Not Started | L31: Hoang
A33: R.M5 | B33: Architecture Justification Document | C33: MILESTONE | D33: 2026-07-07 | E33: 2026-07-25 | F33: 6.5 | G33: 13 | H33: 30 | I33: 14.75 | K33: Not Started | M33: Formal document linking every major design decision to research evidence. Written for tech lead + stakeholders.
A34: R.M5.T1 | B34: Write Path A justification section: Semgrep + CodeQL/Joern + LLM Verifier rationale with paper citations | C34: TASK | I34: 2.33 | K34: Not Started | L34: Hoang
A35: R.M5.T2 | B35: Write Path B justification section: cost-funnel rationale for each tier with paper citations | C35: TASK | I35: 4.5 | K35: Not Started | L35: Hoang
A36: R.M5.T3 | B36: Write Dedup and 5-tier Confidence Scoring justification with triple-path fusion rationale | C36: TASK | I36: 2.33 | K36: Not Started | L36: Hoang
A37: R.M5.T4 | B37: Write Differential Indexer justification: hash-based incremental scanning design | C37: TASK | I37: 1.25 | K37: Not Started | L37: Hoang
A38: R.M5.T5 | B38: Write PoE Layer justification and compile tech-lead narrative summary (<=2 pages for non-technical stakeholders) | C38: TASK | I38: 4.33 | K38: Not Started | L38: Hoang
A40: R.M6 | B40: Ongoing Research Monitoring | C40: MILESTONE | D40: 2026-07-14 | E40: 2026-08-01 | F40: 3.5 | G40: 8.5 | H40: 19 | I40: 9.42 | K40: Not Started | M40: Set up alert infrastructure for post-June-2026 papers. Forward-citation pass on top 5 most-cited papers.
A41: R.M6.T1 | B41: Configure arXiv email digest alerts for all 7 research areas using category filters cs.CR, cs.SE, cs.LG | C41: TASK | I41: 1.08 | K41: Not Started | L41: Hoang
A42: R.M6.T2 | B42: Configure Google Scholar keyword alerts for ZeroTrust.sh-relevant terms | C42: TASK | I42: 1.08 | K42: Not Started | L42: Hoang
A43: R.M6.T3 | B43: Perform forward-citation pass on top 5 most-cited papers in the 40-paper catalogue | C43: TASK | I43: 3.33 | K43: Not Started | L43: Hoang
A44: R.M6.T4 | B44: Write monitoring runbook documenting exact search queries, weekly review steps, monthly deep-search protocol | C44: TASK | I44: 2.17 | K44: Not Started | L44: Hoang
A45: R.M6.T5 | B45: Integrate newly discovered papers into validation matrix; update benchmarks reference table if figures superseded | C45: TASK | I45: 1.75 | K45: Not Started | L45: Hoang

Sheet Constraints
A1: ZeroTrust.sh · Planning Constraints Register
A2: Intern: Ton Minh Hoang · VNG ZingPlay Studio · Last updated: 2026-06-12
A4: ID | B4: Constraint | C4: Category | D4: Impact | E4: Applied To | F4: Buffer Added | G4: Notes
A5: C-01 | B5: Developer has no prior Go experience entering G2 | C5: Experience | D5: High | E5: G2 (M1-M3); G3 (all milestones) | F5: +20% applied to ML estimate on all Go-first tasks in G2 M1-M3 | G5: AI assistance (Copilot / Claude Code) estimated to reduce effective learning time by 40-60% vs. unaided learning. Buffer not reduced — AI reduces blocked-state duration, not probability.
A6: C-02 | B6: 8-week internship window (Jun 9 – Aug 1, 2026) at approximately 6 productive hours per day | C6: Time | D6: High | E6: All goals | F6: Total capacity: ~240 h. Allocated: ~300 h PERT E across all goals. Research milestones interleaved with implementation. | G6: Research milestones (R.M1-R.M6) are designed to be interleaved with implementation work, not sequential. Research reading occurs during low-energy periods; coding during peak focus hours.
A7: C-03 | B7: G1 tech lead presentation is fixed at 2026-06-27 — this date cannot slip | C7: Time | D7: High | E7: G1 (all milestones) | F7: None — date is immovable. Stretch items cut first if M1.4 runs late. | G7: If M1.4 (Finding Schema) is not complete by Jun 26 EOD, any stretch work is automatically cancelled. Demo recording fallback must exist before Jun 26.
A8: C-04 | B8: G2 Path A checkpoint targeted for 2026-07-18 | C8: Time | D8: Medium | E8: G2 (M4) | F8: 2.BUF (13h) provides absorption window. | G8: Date is soft — can slip 1-2 days if integration testing reveals critical bugs. Must not slip past Jul 21 (G3 start date).
A9: C-05 | B9: Demo deadline is 2026-08-06; submission cutoff is 2026-08-08 | C9: Time | D9: High | E9: G4 (all milestones) | F9: 4.BUF (3h) is the only buffer. No slack beyond Aug 8. | G9: G4 is 34h of PERT E in 5 days. Pre-stub of SSVC dedup skeleton and HTML report shell during G3 final week (Jul 28-31) is required to meet this deadline.
A10: C-06 | B10: Ollama LLM runtime requires a 4-8 GB quantized GGUF model download before any LLM task in G2 can begin | C10: Tool | D10: Medium | E10: G2 (M3: LLM Verifier; M3: LLM Semantic Scan) | F10: 0.5 day pre-setup buffer built into the Jun 30 sprint start | G10: Model: CodeLlama-7B-Instruct or Mistral-7B-Instruct-v0.2 (recommended). Download must happen before Jul 11 (M3 start date). Corporate network proxy settings may add setup time.
A11: C-07 | B11: G4 PoE Layer (4.M4) requires Docker Desktop installed and running on the development machine | C11: Environment | D11: Medium | E11: G4 (M4: Docker Sandbox) — stretch only | F11: 0.5 day installation buffer included in 4.M4 PERT E estimate | G11: Corporate machines may have Docker Desktop blocked by IT policy. Fallback: use Podman (drop-in replacement with same Docker SDK API). Verify Docker availability on Aug 1.
A12: C-08 | B12: Semgrep CLI version must be pinned in all demo scripts to ensure reproducible output across machines | C12: Tool | D12: Low | E12: G1 (M1: rule suite); G4 (M3: demo prep) | F12: 1 h included in demo prep tasks to handle version verification | G12: Semgrep YAML rule syntax can differ between minor versions. Pin to the version used during rule development. Document in demo/README.md.
A13: C-09 | B13: Mentor/tech lead review cycles take 2-3 business days per round | C13: Dependency | D13: Medium | E13: All goals — presentation milestones and architecture decisions | F13: Explicit buffer rows in each goal absorb review wait time | G13: Architecture sign-off for G2/G3 is gated on G1 tech lead approval (Jun 27). Submit G1 materials at least 2 days before Jun 27 to allow feedback incorporation.
A14: C-10 | B14: Detailed planning for G2 and G3 is deferred until the G1 tech lead presentation is approved | C14: Dependency | D14: Medium | E14: G2 (start gate); G3 (start gate) | F14: G2 officially starts Jun 30 — 3 days after the G1 presentation, allowing for feedback incorporation. | G14: If G1 tech lead requests major scope changes, G2 milestones may need to be re-estimated. The 3-day gap (Jun 27-30) is intentionally left as a planning and adjustment window.

Sheet Research Papers
A1: ZeroTrust.sh · Research Paper Manager
A2: Smart Paper Manager · Use column dropdowns (▾) to filter by Category, Tags, Read Status · Click any column header to sort · Write your notes in column K
A4: # | B4: Title | C4: Authors | D4: Year | E4: Venue | F4: Category | G4: Tags | H4: Read Status | I4: Relevance to ZeroTrust.sh | J4: URL | K4: Literature Review Notes
A5: 1 | B5: Automated Vulnerability Detection in Source Code Using Deep Representation Learning | C5: Feng et al. | D5: 2026 | E5: arXiv | F5: ML/DL Detection | G5: CNN, deep representation learning, source code, vulnerability classifier | H5: Unread | I5: CNN-based deep representation learning for vulnerability detection — validates ML classifier gate in Path B Tier 2 | J5: https://arxiv.org/abs/2602.23121 | K5: Write your notes here…
A6: 2 | B6: DiverseVul: A New Vulnerable Source Code Dataset for Deep Learning Based Vulnerability Detection | C6: Jia et al. | D6: 2023 | E6: RAID 2023 / ACM | F6: ML/DL Detection | G6: dataset, C/C++, CWE, BigVul alternative, training data, benchmark, 18945 functions | H6: Unread | I6: Largest diverse C/C++ vulnerability dataset (18,945 functions, 150 CWEs) — training data source for Code Vulnerability Classifier | J6: https://arxiv.org/abs/2304.00409 | K6: Write your notes here…
A7: 3 | B7: Vulnerability Detection in C/C++ Code with Deep Learning | C7: Multiple authors | D7: 2024 | E7: arXiv | F7: ML/DL Detection | G7: neural network, program slicing, C/C++, deep learning | H7: Unread | I7: Neural networks with program slices for vulnerability detection — informs Tier 2 classifier design | J7: https://arxiv.org/abs/2405.12384 | K7: Write your notes here…
A8: 4 | B8: Deep Learning Aided Software Vulnerability Detection: A Survey | C8: Survey authors | D8: 2025 | E8: arXiv | F8: ML/DL Detection | G8: survey, deep learning, vulnerability detection, baseline comparison | H8: Unread | I8: Comprehensive DL survey for vulnerability detection — baseline reference for Tier 2 classifier selection | J8: https://arxiv.org/abs/2503.04002 | K8: Write your notes here…
A9: 5 | B9: Software Vulnerability Detection Using a Lightweight Graph Neural Network (VulGNN) | C9: Zhu et al. | D9: 2026 | E9: arXiv | F9: Graph Neural Networks | G9: GNN, lightweight, LLM-parity, local inference, classifier, small model | H9: Unread | I9: Lightweight GNN achieving LLM-parity at 100x smaller size — validates cheap local classifier concept in new architecture | J9: https://arxiv.org/abs/2603.29216 | K9: Write your notes here…
A10: 6 | B10: Vul-LMGNNs: Fusing Language Models and Graph Neural Networks for Code Vulnerability Detection | C10: Rong et al. | D10: 2024 | E10: arXiv | F10: Graph Neural Networks | G10: GNN, language model, hybrid, code representation, code LM | H10: Unread | I10: Hybrid code LM + GNN — informs Call Graph + Classifier integration in Path B Tier 2 | J10: https://arxiv.org/abs/2404.14719 | K10: Write your notes here…
A11: 7 | B11: Structure-Aware Code Vulnerability Analysis With Graph Neural Networks | C11: Allamanis et al. | D11: 2024 | E11: arXiv | F11: Graph Neural Networks | G11: GNN, Java, structure-aware, vulnerability fixing, commit-level | H11: Unread | I11: GNN-based vulnerability analysis using Java vulnerability-fixing commits — informs structure-aware detection | J11: https://arxiv.org/abs/2307.11454 | K11: Write your notes here…
A12: 8 | B12: Graph Neural Networks for Vulnerability Detection: A Counterfactual Explanation | C12: Li et al. | D12: 2024 | E12: arXiv | F12: Graph Neural Networks | G12: GNN, explainability, counterfactual, confidence scoring, interpretability | H12: Unread | I12: Explainability analysis of GNN detection — informs confidence scoring in Dedup layer | J12: https://arxiv.org/abs/2404.15687 | K12: Write your notes here…
A13: 9 | B13: ReGVD: Revisiting Graph Neural Networks for Vulnerability Detection | C13: Nguyen et al. | D13: 2022 | E13: ACM/IEEE | F13: Graph Neural Networks | G13: GNN, token sequence, baseline, benchmark, foundational | H13: Unread | I13: Foundational GNN model treating source code as flat token sequences — baseline for Tier 2 classifier | J13: https://dl.acm.org/doi/abs/10.1145/3510454.3516865 | K13: Write your notes here…
A14: 10 | B14: LineVD: Statement-level Vulnerability Detection using Graph Neural Networks | C14: Chen et al. | D14: 2022 | E14: arXiv | F14: Graph Neural Networks | G14: GNN, statement-level, line localization, fine-grained, HTML report | H14: Unread | I14: Fine-grained GNN vulnerability localization — informs line-level finding output in HTML report | J14: https://arxiv.org/abs/2203.05181 | K14: Write your notes here…
A15: 11 | B15: LLMs in Code Vulnerability Analysis: A Proof of Concept | C15: Kochling et al. | D15: 2026 | E15: arXiv | F15: LLM Code Analysis | G15: LLM, empirical, proof-of-concept, zero-shot, Path B validation | H15: Unread | I15: Empirical PoC for LLM vulnerability analysis — validates LLM Semantic Scan role in Path B Tier 3 | J15: https://arxiv.org/abs/2601.08691 | K15: Write your notes here…
A16: 12 | B16: IRIS: LLM-Assisted Static Analysis for Detecting Security Vulnerabilities | C16: Scanlon et al. | D16: 2024 | E16: arXiv | F16: LLM Code Analysis | G16: hybrid SAST+LLM, false positive, 80% FP reduction, IRIS, key paper | H16: Unread | I16: Hybrid SAST+LLM detecting 55/120 vulns + 6 new, reducing FP by 80% — directly validates ZeroTrust.sh hybrid design | J16: https://arxiv.org/abs/2405.17238 | K16: Write your notes here…
... A90: 68 | B90: PoCGen: Generating Proof-of-Concept Exploits for Vulnerabilities in NPM Packages | C90: Shen et al. | D90: 2025 | E90: arXiv:2506.04962 | F90: Exploit Automation | G90: PoC generation, npm, JavaScript, Node.js, 77% success rate, CVE disclosure, ecosystem-specific | H90: Unread | I90: Autonomous LLM-based PoC for npm vulnerabilities (77% on SecBench.js); 6 PoCs in official CVE disclosures — demonstrates ecosystem-specific PoE applicability for JavaScript targets. | J90: https://arxiv.org/abs/2506.04962 | K90: Write your notes here…
A92: Read Status: Unread (gray) — not yet read · Reading (amber) — in progress · Read (blue) — finished · Reviewed (green) — literature review written · Filter tip: click ▾ on Category or Tags header to filter by research area
